Workbook
Name hh: #REF!
Name hh: #REF!
Name hh: #REF!
Name riesgopais: #REF!
Name riesgopais: #REF!
Name Tabla3_RFFRFR: Tabla3[]
Name Tabla3_RFFRFRcustom: Tabla3[]
Name Tabla3_RFFRFRustom: Tabla3[]

Sheet Plantilla Usuario
B2: Fecha | C2: 45838
B3: País | C3: Peru
B4: Moneda | C4: Dólares
B5: Acciones | C5: 847191.73
B7: Primer año de información histórica (Anual) | C7: 2017
B8: Último año de información histórica (Anual) | C8: 2021
B9: Entrada EE.FF. | C9: 3289719;;;;3289719;3826276;;1865624;1198090;;;3826276;7115995;;;;2823965;;;;1391745;4215710;2900285;;;;2900285;7115995 | D9: 4103986;;;;4103986;4955240;;2537852;1361126;;;4955240;9059226;;;;3084554;;;;2729104;5813658;3245568;;;;3245568;9059226 | E9: 4490817;;;;4490817;6751464;;3323015;1540298;;;6751464;11242281;;;;3462553;;;;4321222;7783775;3458506;;;;3458506;11242281 | F9: 4618768;;;;4618768;7031343;;3410774;1801309;;;7031343;11650111;558545;;;3604331;3515304;;;4364956;7969287;3680824;;;;3680824;11650111 | G9: 6509850;;;;6509850;6898453;;3343589;1973854;;;6898453;13408303;639174;;;4645551;4676131;;;5437375;10082926;3325377;;;;3325377;13408303 | K9: 2017;3289719;;;;3289719;3826276;;1865624;1198090;;;3826276;7115995;;;;2823965;;;;1391745;4215710;2900285;;;;2900285;7115995;;;2017;6949265;-5042402;1906863;-633605;164314;-487579;-42607;743072;;;;;;;;;;;;;;;;;;;;;;;;;;;;;;;;;;;;;;;;
B10: BALANCE GENERAL | C10: =C7 -> 2017 | D10: =IF(C10<YEAR($C$2)-1,C10+1,"") -> 2018 | E10: =IF(D10<$C$8,D10+1,"") -> 2019 | F10: =IF(E10<$C$8,E10+1,"") -> 2020 | G10: =IF(F10<$C$8,F10+1,"") -> 2021 | H10: =IF(G10<$C$8,G10+1,"") | I10: =IF(H10<$C$8,H10+1,"") -> #VALUE! | J10: =IF(I10<$C$8,I10+1,"") -> #VALUE!
B11: Efectivo y Equivalentes al Efectivo | C11: {=IF(ISBLANK(C9), "", TRANSPOSE(IFERROR(VALUE(_xlfn.TEXTSPLIT(C9,";")),0)))} | D11: {=IF(ISBLANK(D9), "", TRANSPOSE(IFERROR(VALUE(_xlfn.TEXTSPLIT(D9,";")),0)))} | E11: {=IF(ISBLANK(E9), "", TRANSPOSE(IFERROR(VALUE(_xlfn.TEXTSPLIT(E9,";")),0)))} | F11: {=IF(ISBLANK(F9), "", TRANSPOSE(IFERROR(VALUE(_xlfn.TEXTSPLIT(F9,";")),0)))} | G11: {=IF(ISBLANK(G9), "", TRANSPOSE(IFERROR(VALUE(_xlfn.TEXTSPLIT(G9,";")),0)))}
B12: Cuentas por Cobrar Comerciales y Otras Cuentas por Cobrar | C12: 0 | D12: 0 | E12: 0 | F12: 0 | G12: 0
B13: Inventarios | C13: 0 | D13: 0 | E13: 0 | F13: 0 | G13: 0
B14: Otros activos no financieros | C14: 0 | D14: 0 | E14: 0 | F14: 0 | G14: 0
B15: Total Activos Corrientes | C15: 3289719 | D15: 4103986 | E15: 4490817 | F15: 4618768 | G15: 6509850
B16: Cuentas por Cobrar Comerciales y Otras Cuentas por Cobrar | C16: 3826276 | D16: 4955240 | E16: 6751464 | F16: 7031343 | G16: 6898453
B17: Inversiones Financieras e inmobiliarias | C17: 0 | D17: 0 | E17: 0 | F17: 0 | G17: 0
B18: Propiedades, Planta y Equipo | C18: 1865624 | D18: 2537852 | E18: 3323015 | F18: 3410774 | G18: 3343589
B19: Depreciación Acumulada* | C19: 1198090 | D19: 1361126 | E19: 1540298 | F19: 1801309 | G19: 1973854
B20: Activos Intangibles | C20: 0 | D20: 0 | E20: 0 | F20: 0 | G20: 0
B21: Otros activos no financieros | C21: 0 | D21: 0 | E21: 0 | F21: 0 | G21: 0
B22: Total Activos No Corrientes | C22: 3826276 | D22: 4955240 | E22: 6751464 | F22: 7031343 | G22: 6898453
B23: TOTAL ACTIVOS | C23: 7115995 | D23: 9059226 | E23: 11242281 | F23: 11650111 | G23: 13408303
... B38: TOTAL PASIVOS Y PATRIMONIO | C38: 7115995 | D38: 9059226 | E38: 11242281 | F38: 11650111 | G38: 13408303
B40: Entrada EE.RR. | C40: 6949265;-5042402;1906863;-633605;164314;-487579;-42607;743072;;;;;; | D40: 8288702;-6244012;2044690;-681336;202775;-603139;26059;786274;;;;;; | E40: 9872187;-7420013;2452174;-801905;298028;-651838;-49856;948575;;;;;; | F40: 10131767;-7712254;2419513;-862157;286071;-688428;-75085;793843;;;;;; | G40: 12227663;-9831454;2396209;-786246;232476;-732928;39531;916566;;-337756;;;;
B41: ESTADO DE RESULTADOS | C41: =C10 -> 2017 | D41: =D10 -> 2018 | E41: =E10 -> 2019 | F41: =F10 -> 2020 | G41: =G10 -> 2021 | H41: =H10
B42: Ingresos de Actividades Ordinarias | C42: {=IF(ISBLANK(C40), "", TRANSPOSE(IFERROR(VALUE(_xlfn.TEXTSPLIT(C40,";")),0)))} | D42: {=IF(ISBLANK(D40), "", TRANSPOSE(IFERROR(VALUE(_xlfn.TEXTSPLIT(D40,";")),0)))} | E42: {=IF(ISBLANK(E40), "", TRANSPOSE(IFERROR(VALUE(_xlfn.TEXTSPLIT(E40,";")),0)))} | F42: {=IF(ISBLANK(F40), "", TRANSPOSE(IFERROR(VALUE(_xlfn.TEXTSPLIT(F40,";")),0)))} | G42: {=IF(ISBLANK(G40), "", TRANSPOSE(IFERROR(VALUE(_xlfn.TEXTSPLIT(G40,";")),0)))}
B43: Costo de Ventas | C43: -5042402 | D43: -6244012 | E43: -7420013 | F43: -7712254 | G43: -9831454
B44: Utilidad Bruta | C44: 1906863 | D44: 2044690 | E44: 2452174 | F44: 2419513 | G44: 2396209
B45: Gastos de Ventas y Distribución | C45: -633605 | D45: -681336 | E45: -801905 | F45: -862157 | G45: -786246
B46: Depreciación* | C46: 164314 | D46: 202775 | E46: 298028 | F46: 286071 | G46: 232476
B47: Gastos de Administración | C47: -487579 | D47: -603139 | E47: -651838 | F47: -688428 | G47: -732928
B48: Otros ingresos (gastos) netos | C48: -42607 | D48: 26059 | E48: -49856 | F48: -75085 | G48: 39531
B49: Utilidad Operativa | C49: 743072 | D49: 786274 | E49: 948575 | F49: 793843 | G49: 916566
B50: Ingresos financieros | C50: 0 | D50: 0 | E50: 0 | F50: 0 | G50: 0
B51: Gastos financieros | C51: 0 | D51: 0 | E51: 0 | F51: 0 | G51: -337756
B52: Diferencia en cambio, neta | C52: 0 | D52: 0 | E52: 0 | F52: 0 | G52: 0
B53: Utilidad antes de impuesto a la renta | C53: 0 | D53: 0 | E53: 0 | F53: 0 | G53: 0
B54: Impuesto a la renta | C54: 0 | D54: 0 | E54: 0 | F54: 0 | G54: 0
B55: Utilidad neta | C55: 0 | D55: 0 | E55: 0 | F55: 0 | G55: 0
B70: Columna1 | C70: Columna2 | E70: Columna1 | F70: Columna2 | G70: Columna3 | H70: Columna4
B71: Empresa concepto | C71: ='M. por conceptos'!L195 -> 0 | E71: $$FVBGH$$ | F71: Fecha | G71: =C2 -> 45838
...

Sheet WACC
B3: Tratamiento del Rf | C3: Bono EE.UU | E3: Fecha | F3: ='Plantilla Usuario'!C2 -> 45838 | H3: Costo de deuda (Kd) | I3: =ROUND(-HLOOKUP('Plantilla Usuario'!$C$8,'Plantilla Usuario'!B10:Q55,42)/(HLOOKUP('Plantilla Usuario'!$C$8-1,'Plantilla Usuario'!B10:G38,15)+HLOOKUP('Plantilla Usuario'!$C$8-1,'Plantilla Usuario'!B10:G38,19)),4) -> 0.0829 | J3: =+'Plantilla Usuario'!C4 -> Dólares | N3: 1. Evolución del Be
A5: I. | B5: Parametros generales | D5: VI. | E5: Parámetros para el mercado emergente | G5: VI. | H5: Parámetros para la empresa | O5: Rm Promedio | P5: Rf Promedio | Q5: Rf Spot
B6: Bono EE.UU seleccionado | C6: 1 | D6: años | E6: País | F6: ='Plantilla Usuario'!C3 -> Peru | I6: Dólares | J6: Dev. esperada | K6: Moneda Nac | N6: Mercado Desarrollado | O6: ='Prima de mercado'!C$3 -> 0.11821279 | P6: ='Prima de mercado'!$D$3 -> 0.051104658 | Q6: =$C$10 -> 0.0416
B7: Bono del Rf ajustado | C7: ='Rf Ajustado'!E11 -> 2.8477432 | D7: años | E7: Devaluación Esperada | F7: 0.0164 | I7: =IF($K$7=0,0,(1+$K$7)/(1+$J$7)-1) -> 0 | J7: =$F$7 -> 0.0164 | K7: =IF($J$3="Soles",I3,0) -> 0 | N7: Mercado Emergente | O7: ='Prima de mercado'!C$3 -> 0.11821279 | P7: ='Prima de mercado'!$D$3 -> 0.051104658 | Q7: =$C$10 -> 0.0416
H8: Costo de deuda (Kd) | I8: =IF($J$3="Dólares",$I$3,0) -> 0.0829 | J8: =$F$7 -> 0.0164 | K8: =IF(I8=0,0,(1+$I$8)*(1+$J$8)-1) -> 0.10065956 | N8: Empresa | O8: ='Prima de mercado'!C$3 -> 0.11821279 | P8: ='Prima de mercado'!$D$3 -> 0.051104658 | Q8: =$C$10 -> 0.0416
B9: Prima de Mercado (Rm -Rf) | C9: =VLOOKUP(YEAR($F$3),'Prima de mercado'!A2:D7,2) -> 0.066379627 | E9: Riesgo país | F9: =VLOOKUP($F$6,Embi!$L$2:$M$11,2,FALSE)/10000 -> 0.015438095
B10: Tasa libre de Riesgo (Rf) | C10: =IF($C$3="Bono EE.UU",VLOOKUP($C$6,'Rf Ajustado'!$A$14:$B$25,2,FALSE),'Rf Ajustado'!$E$12) -> 0.0416 | H10: Prima empresa | I10: =IF(J3="Dólares",I3-F33,I7-F33) -> 0.0058619048
N11: 2. Formación de las tasas
A12: II. | B12: Parámetros del sector de referencia
B13: Sector | C13: Publicidad | N13: Mercado desarrollado | AN13: WACC (Capitalización de Mercado) - Método por conceptos
O14: Ke | P14: Koa | Q14: Kd
B15: MERCADO DESARROLLADO | E15: MERCADO EMERGENTE | H15: EMPRESA | N15: Rf | O15: =$C$10 -> 0.0416 | P15: =$C$10 -> 0.0416 | Q15: =$C$10 -> 0.0416 | AN15: Porcentaje de deuda (%D) | AO15: =('EE.FF Económicos'!$H$17+'EE.FF Económicos'!$H$21)/('EE.FF Económicos'!$H$17+'EE.FF Económicos'!$H$21+'M. por conceptos'!$L$184) -> -43.54309
N16: Riesgo de negocio | O16: =C9*C21 -> 0.04971834 | AN16: Porcentaje de Capital (%C) | AO16: =1-AO15 -> 44.54309
B17: Porcentaje de deuda (%D) | C17: =IF(AND(WACC!$F$3>Tablas!$I$3,WACC!$F$3<=Tablas!$J$6), VLOOKUP(WACC!$C$13,'Damondaran Industries'!$A$1:$AE$95,2 + 6 * ROUNDDOWN((WACC!$F$3 - Tablas!$I$3) / (Tablas!$J$6 - Tablas!$I$3) * 3, 0), FALSE), VLOOKUP(WACC!$C$13,'Damondaran Industries'!$A$1:$AE$95,7,FALSE) ) -> 0.31029224 | E17: Porcentaje de deuda (%D) | F17: =IF(G17,G17,C17) -> 0.31029224 | H17: Porcentaje de deuda (%D) | I17: =ROUND(('EE.FF Económicos'!H17+'EE.FF Económicos'!H21)/('EE.FF Económicos'!H17+'EE.FF Económicos'!H21+'EE.FF Económicos'!H26),4) -> 0.6151 | N17: Riesgo económico de negocio | P17: =C27*C9 -> 0.037768475 | AN17: Ratio D/C | AO17: =AO15/AO16 -> -0.97754983
B18: Porcentaje de Capital (%C) | C18: =IF(AND(WACC!$F$3>Tablas!$I$3,WACC!$F$3<=Tablas!$J$6), VLOOKUP(WACC!$C$13,'Damondaran Industries'!$A$1:$AE$95,3 + 6 * ROUNDDOWN((WACC!$F$3 - Tablas!$I$3) / (Tablas!$J$6 - Tablas!$I$3) * 3, 0), FALSE), VLOOKUP(WACC!$C$13,'Damondaran Industries'!$A$1:$AE$95,7,FALSE) ) -> 0.68970776 | E18: Porcentaje de Capital (%C) | F18: =1-F17 -> 0.68970776 | H18: Porcentaje de Capital (%C) | I18: =1-I17 -> 0.3849 | N18: Spread de la deuda | Q18: =C32 -> 0.02 | AN18: Tasa de Impuesto (T) | AO18: =+I20 -> 0.295
B19: Ratio D/C | C19: 0.5186 | E19: Ratio D/C | F19: =F17/F18 -> 0.44988945 | H19: Ratio D/C | I19: =I17/I18 -> 1.5980774 | O19: =SUM(O15:O18) -> 0.09131834 | P19: =SUM(P15:P18) -> 0.079368475 | Q19: =SUM(Q15:Q18) -> 0.0616 | AN19: Beta apalancado (Be) | AO19: =$C$27*(1+(1-$AO$18)*$AO$17) -> 0.1768536
B20: Tasa de Impuesto (T) | C20: 0.3899 | E20: Tasa de Impuesto (T) | F20: 0.295 | H20: Tasa de Impuesto (T) | I20: =+F20 -> 0.295 | Q20: =Q19*(1-C20) -> 0.03758216
B21: Beta apalancado (Be) | C21: 0.749 | E21: Beta apalancado (Be) | F21: =$C$27*(1+(1-$F$20)*$F$19) -> 0.7494405 | H21: Beta apalancado (Be) | I21: =$C$27*(1+(1-$I$20)*$I$19) -> 1.2100117 | AO21: Dólares | AP21: Moneda Nacional
AN22: Costo de Capital Financiero (Ke) | AO22: =$C$10+$AO$19*$C$9+$F$9+$I$10 -> 0.074639476 | AP22: =(1+$AO$22)*(1+$J$7)-1 -> 0.092263563
A23: III. | B23: Determinación del Costo de Capital Financiero | I23: Dólares | J23: Moneda Nacional | N23: Mercado emergente
A24: Ke = rf + Be (Rm-rf) | B24: Costo de Capital Financiero (Ke) | C24: =$C$10+$C$21*$C$9 -> 0.09131834 | E24: Costo de Capital Financiero (Ke) | F24: =$C$10+$F$21*$C$9+$F$9 -> 0.10678568 | H24: Costo de Capital Financiero (Ke) | I24: =ROUND($C$10+$I$21*$C$9+$F$9+$I$10,4) -> 0.1432 | J24: =ROUND((1+$I$24)*(1+$J$7)-1,4) -> 0.1619 | O24: Ke | P24: Koa | Q24: Kd
N25: Rf | O25: =O15 -> 0.0416 | P25: =P15 -> 0.0416 | Q25: =Q15 -> 0.0416 | AO25: Dólares | AP25: Moneda Nacional
A26: IV. | B26: Determinación del Costo de Capital Económico | N26: Riesgo de negocio | O26: =F21*C9 -> 0.049747581 | AN26: Costo de Capital Económico (Koa) | AO26: =$F$28+$I$10 -> 0.10066848 | AP26: =(1+$AO$26)*(1+$J$7)-1 -> 0.11871944
A27: Koa = rf + Boa (Rm-rf) | B27: Beta desapalancado (Boa) | C27: =$C$21/(1+(1-$C$20)*$C$19) -> 0.56897692 | E27: Beta desapalancado (Boa) | F27: =$F$21/(1+(1-$F$20)*$F$19) -> 0.56897692 | I27: Dólares | J27: Moneda Nacional | N27: Riesgo económico de negocio | P27: =F27*C9 -> 0.037768475
B28: Costo de Capital Económico (Koa) | C28: =$C$10+$C$27*$C$9 -> 0.079368475 | E28: Costo de Capital Económico (Koa) | F28: =$C$10+$F$27*$C$9+$F$9 -> 0.094806571 | H28: Costo de Capital Económico (Koa) | I28: =ROUND($F$28+$I$10,4) -> 0.1007 | J28: =ROUND((1+$I$28)*(1+$J$7)-1,4) -> 0.1188 | N28: Spread de la deuda | Q28: =C32 -> 0.02
N29: Riesgo país | O29: =$F$9 -> 0.015438095 | P29: =$F$9 -> 0.015438095 | Q29: =$F$9 -> 0.015438095
A30: V. | B30: Determinación de la Prima de Riesgo sobre la Deuda | O30: =SUM(O25:O29) -> 0.10678568 | P30: =SUM(P25:P29) -> 0.094806571 | Q30: =SUM(Q25:Q29) -> 0.077038095 | AO30: Dólares | AP30: Moneda Nacional
B31: Desviación estandar | C31: =IF(AND(WACC!$F$3>Tablas!$I$3,WACC!$F$3<=Tablas!$J$6), VLOOKUP(WACC!$C$13,'Damondaran Industries'!$A$1:$AE$95,6 + 6 * ROUNDDOWN((WACC!$F$3 - Tablas!$I$3) / (Tablas!$J$6 - Tablas!$I$3) * 3, 0), FALSE), VLOOKUP(WACC!$C$13,'Damondaran Industries'!$A$1:$AE$95,7,FALSE) ) -> 0.52722114 | Q31: =Q30*(1-F20) -> 0.054311857 | AN31: Costo de deuda (Kd) | AO31: =IF($I$7="",$I$8,$I$7) -> 0 | AP31: =(1+$AO$31)*(1+$J$7)-1 -> 0.0164
B32: Spread de la deuda | C32: =IF(AND(WACC!$F$3>Tablas!$I$3,WACC!$F$3<=Tablas!$J$6), VLOOKUP(WACC!$C$13,'Damondaran Industries'!$A$1:$AE$95,7 + 6 * ROUNDDOWN((WACC!$F$3 - Tablas!$I$3) / (Tablas!$J$6 - Tablas!$I$3) * 3, 0), FALSE), VLOOKUP(WACC!$C$13,'Damondaran Industries'!$A$1:$AE$95,7,FALSE) ) -> 0.02 | I32: DÓLARES | J32: Moneda Nacional | AN32: Costo de deuda despúes de impuestos (Kd(1-T)) | AO32: =AO31*(1-$AO$18) -> 0 | AP32: =$AP$31*(1-$I$20) -> 0.011562
A33: Kd = rf + Spread de la deuda | B33: Costo de deuda (Kd) | C33: =$C$10+C32 -> 0.0616 | E33: Costo de deuda (Kd) | F33: =$C$33+$F$9 -> 0.077038095 | H33: Costo de deuda (Kd) | I33: =ROUND(IF($J$3="DÓLARES",$I$8,$I$7),4) -> 0.0829 | J33: =ROUND((1+$I$33)*(1+$J$7)-1,4) -> 0.1007 | N33: Empresa
B34: Costo de deuda despúes de impuestos (Kd(1-T)) | C34: =$C$33*(1-$C$20) -> 0.03758216 | E34: Costo de deuda despúes de impuestos (Kd(1-T)) | F34: =$F$33*(1-$F$20) -> 0.054311857 | H34: Costo de deuda despúes de impuestos (Kd(1-T)) | I34: =ROUND(I33*(1-$I$20),4) -> 0.0584 | J34: =ROUND($J$33*(1-$I$20),4) -> 0.071 | O34: Ke | P34: Koa | Q34: Kd | AO34: Dólares | AP34: Moneda Nacional
N35: Rf | O35: =$O$25 -> 0.0416 | P35: =$O$25 -> 0.0416 | Q35: =$O$25 -> 0.0416 | AN35: Costo Promedio Ponderado de Capital (CPPC) | AO35: =$AO$22*$AO$16+$AO$32*$AO$15 -> 3.3246729 | AP35: =(1+$AO$35)*(1+$J$7)-1 -> 3.3955975
A36: VI. | B36: Determinación del CPPC | I36: Dólares | J36: Moneda Nacional | N36: Riesgo de negocio | O36: =I21*C9 -> 0.080320124
B37: Costo Promedio Ponderado de Capital (CPPC) | C37: =$C$24*$C$18+$C$34*$C$17 -> 0.07464442 | E37: Costo Promedio Ponderado de Capital (CPPC) | F37: =$F$24*$F$18+$F$34*$F$17 -> 0.090503457 | H37: Costo Promedio Ponderado de Capital (CPPC) | I37: =ROUND($I$24*$I$18+$I$34*$I$17,4) -> 0.091 | J37: =ROUND((1+$I$37)*(1+$J$7)-1,4) -> 0.1089 | N37: Riesgo económico de negocio | P37: =C27*C9 -> 0.037768475
N38: Spread de la deuda | Q38: =$C$32 -> 0.02 | AN38: CPPC | AO38: =IF('EE.FF Económicos'!$D$54="Soles",AP35,AO35) -> 3.3955975
A39: VII. | B39: Riesgos de negocio | N39: Riesgo país | O39: =$F$9 -> 0.015438095 | P39: =$F$9 -> 0.015438095 | Q39: =$F$9 -> 0.015438095
B40: Riesgo de negocio financiero (φf) | C40: =C24-C10 -> 0.04971834 | E40: Riesgo de negocio financiero (φf) | F40: =F24-C10-F9 -> 0.049747581 | H40: Riesgo de negocio financiero (φf) | I40: =ROUND(I24-C10-F9-I10,4) -> 0.0803 | N40: Prima empresa | O40: =$I$10 -> 0.0058619048 | P40: =$I$10 -> 0.0058619048 | Q40: =$I$10 -> 0.0058619048
B41: Riesgo de negocio económico (φe) | C41: =C28-C10 -> 0.037768475 | E41: Riesgo de negocio económico (φe) | F41: =F28-C10-F9 -> 0.037768475 | H41: Riesgo de negocio económico (φe) | I41: =ROUND(I28-C10-F9-I10,4) -> 0.0378 | O41: =SUM(O35:O40) -> 0.14322012 | P41: =SUM(P35:P40) -> 0.10066848 | Q41: =SUM(Q35:Q40) -> 0.0829
Q42: =Q41*(1-I20) -> 0.0584445
H44: CPPC | I44: =ROUND(IF('Plantilla Usuario'!C4="Soles",J37,I37),4) -> 0.091
...

Sheet Damondaran Industries
B1: 2021 | C1: 2021 | D1: 2021 | E1: 2021 | F1: 2021 | G1: 2021 | H1: 2022 | I1: 2022 | J1: 2022 | K1: 2022 | L1: 2022 | M1: 2022 | N1: 2023 | O1: 2023 | P1: 2023 | Q1: 2023 | R1: 2023 | S1: 2023 | T1: 2024 | U1: 2024 | V1: 2024 | W1: 2024 | X1: 2024 | Y1: 2024 | Z1: 2025 | AA1: 2025 | AB1: 2025 | AC1: 2025 | AD1: 2025 | AE1: 2025
A2: Industry Name | B2: D/(D+E) | C2: E/(D+E) | D2: Tax rate2 | E2: Beta | F2: Std Dev in Stock | G2: Spread Debt | H2: D/(D+E) | I2: E/(D+E) | J2: Tax rate2 | K2: Beta | L2: Std Dev in Stock | M2: Spread debt | N2: D/(D+E) | O2: E/(D+E) | P2: Tax rate2 | Q2: Beta | R2: Std Dev in Stock | S2: Spread Debt | T2: D/(D+E) | U2: E/(D+E) | V2: Tax rate2 | W2: Beta | X2: Std Dev in Stock | Y2: Spread Debt | Z2: D/(D+E) | AA2: E/(D+E) | AB2: Tax rate2 | AC2: Beta | AD2: Std Dev in Stock | AE2: Spread Debt
A3: Publicidad | B3: 0.33979075 | C3: 0.66020925 | D3: 0.27 | E3: 1.3404215 | F3: 0.56696815 | G3: 0.02068 | H3: 0.33979075 | I3: 0.66020925 | J3: 0.27 | K3: 1.3404215 | L3: 0.56696815 | M3: 0.02068 | N3: 0.31029224 | O3: 0.68970776 | P3: 0.25 | Q3: 1.6317381 | R3: 0.52722114 | S3: 0.02 | T3: 0.25241808 | U3: 0.74758192 | V3: 0.25 | W3: 1.3723256 | X3: 0.56414425 | Y3: 0.014724 | Z3: 0.20758669 | AA3: 0.79241331 | AB3: 0.25 | AC3: 1.3372941 | AD3: 0.67185667 | AE3: 0.0183
A4: Aeroespacial/ Defensa | B4: 0.2275095 | C4: 0.7724905 | D4: 0.27 | E4: 1.2810484 | F4: 0.38232192 | G4: 0.0165 | H4: 0.2275095 | I4: 0.7724905 | J4: 0.27 | K4: 1.2810484 | L4: 0.38232192 | M4: 0.0165 | N4: 0.20670884 | O4: 0.79329116 | P4: 0.25 | Q4: 1.4141823 | R4: 0.37555545 | S4: 0.0162 | T4: 0.20291778 | U4: 0.79708222 | V4: 0.25 | W4: 1.076405 | X4: 0.3640215 | Y4: 0.012055 | Z4: 0.18562455 | AA4: 0.81437545 | AB4: 0.25 | AC4: 0.90155313 | AD4: 0.42742401 | AE4: 0.0095
A5: Transporte aéreo | B5: 0.60525992 | C5: 0.39474008 | D5: 0.27 | E5: 1.5829076 | F5: 0.40193094 | G5: 0.02068 | H5: 0.60525992 | I5: 0.39474008 | J5: 0.27 | K5: 1.5829076 | L5: 0.40193094 | M5: 0.02068 | N5: 0.65075796 | O5: 0.34924204 | P5: 0.25 | Q5: 1.4159651 | R5: 0.37727499 | S5: 0.0162 | T5: 0.61854039 | U5: 0.38145961 | V5: 0.25 | W5: 1.2668402 | X5: 0.44650999 | Y5: 0.012055 | Z5: 0.51650226 | AA5: 0.48349774 | AB5: 0.25 | AC5: 1.2360067 | AD5: 0.65271639 | AE5: 0.0183
A6: Confección de ropa | B6: 0.24009984 | C6: 0.75990016 | D6: 0.27 | E6: 1.2265826 | F6: 0.43487047 | G6: 0.02068 | H6: 0.24009984 | I6: 0.75990016 | J6: 0.27 | K6: 1.2265826 | L6: 0.43487047 | M6: 0.02068 | N6: 0.34024907 | O6: 0.65975093 | P6: 0.25 | Q6: 1.3246974 | R6: 0.38508747 | S6: 0.0162 | T6: 0.3277875 | U6: 0.6722125 | V6: 0.25 | W6: 1.1946999 | X6: 0.3703551 | Y6: 0.012055 | Z6: 0.3145444 | AA6: 0.6854556 | AB6: 0.25 | AC6: 0.99056805 | AD6: 0.50926388 | AE6: 0.012
A7: Automóviles y Camiones | B7: 0.16570496 | C7: 0.83429504 | D7: 0.27 | E7: 1.1293063 | F7: 0.5477688 | G7: 0.02068 | H7: 0.16570496 | I7: 0.83429504 | J7: 0.27 | K7: 1.1293063 | L7: 0.5477688 | M7: 0.02068 | N7: 0.33418107 | O7: 0.66581893 | P7: 0.25 | Q7: 1.5405977 | R7: 0.52614125 | S7: 0.02 | T7: 0.23675434 | U7: 0.76324566 | V7: 0.25 | W7: 1.5223779 | X7: 0.59698514 | Y7: 0.014724 | Z7: 0.18297971 | AA7: 0.81702029 | AB7: 0.25 | AC7: 1.6154126 | AD7: 0.77591112 | AE7: 0.0183
A8: Partes de Automóviles | B8: 0.24056373 | C8: 0.75943627 | D8: 0.27 | E8: 1.3980689 | F8: 0.3714042 | G8: 0.02068 | H8: 0.24056373 | I8: 0.75943627 | J8: 0.27 | K8: 1.3980689 | L8: 0.3714042 | M8: 0.0165 | N8: 0.29901008 | O8: 0.70098992 | P8: 0.25 | Q8: 1.4739918 | R8: 0.39519395 | S8: 0.0162 | T8: 0.27766272 | U8: 0.72233728 | V8: 0.25 | W8: 1.3444266 | X8: 0.37071964 | Y8: 0.012055 | Z8: 0.32356185 | AA8: 0.67643815 | AB8: 0.25 | AC8: 1.2251238 | AD8: 0.52623749 | AE8: 0.012
A9: Bebida alcohólicas | B9: 0.1763857 | C9: 0.8236143 | D9: 0.27 | E9: 0.81936465 | F9: 0.37865996 | G9: 0.0165 | H9: 0.1763857 | I9: 0.8236143 | J9: 0.27 | K9: 0.81936465 | L9: 0.37865996 | M9: 0.0165 | N9: 0.18639448 | O9: 0.81360552 | P9: 0.25 | Q9: 1.0129742 | R9: 0.49874676 | S9: 0.0162 | T9: 0.19656022 | U9: 0.80343978 | V9: 0.25 | W9: 1.1318349 | X9: 0.4970414 | Y9: 0.012055 | Z9: 0.23351097 | AA9: 0.76648903 | AB9: 0.25 | AC9: 0.61029786 | AD9: 0.63076376 | AE9: 0.012
A10: Bebidas sin alcohol | B10: 0.14271344 | C10: 0.85728656 | D10: 0.27 | E10: 1.2156865 | F10: 0.48265389 | G10: 0.02068 | H10: 0.14271344 | I10: 0.85728656 | J10: 0.27 | K10: 1.2156865 | L10: 0.48265389 | M10: 0.02068 | N10: 0.1324644 | O10: 0.8675356 | P10: 0.25 | Q10: 1.3034433 | R10: 0.41717147 | S10: 0.0162 | T10: 0.14615788 | U10: 0.85384212 | V10: 0.25 | W10: 0.76414588 | X10: 0.42961071 | Y10: 0.012055 | Z10: 0.16479515 | AA10: 0.83520485 | AB10: 0.25 | AC10: 0.5677661 | AD10: 0.47670268 | AE10: 0.012
A11: Radiofusión | B11: 0.53879276 | C11: 0.46120724 | D11: 0.27 | E11: 1.3520953 | F11: 0.4876941 | G11: 0.02068 | H11: 0.53879276 | I11: 0.46120724 | J11: 0.27 | K11: 1.3520953 | L11: 0.4876941 | M11: 0.02068 | N11: 0.59486627 | O11: 0.40513373 | P11: 0.25 | Q11: 1.3220586 | R11: 0.46898415 | S11: 0.0162 | T11: 0.63820799 | U11: 0.36179201 | V11: 0.25 | W11: 1.0609244 | X11: 0.38457134 | Y11: 0.012055 | Z11: 0.59929947 | AA11: 0.40070053 | AB11: 0.25 | AC11: 0.91752363 | AD11: 0.52595168 | AE11: 0.012
A12: Corretaje e inversión bancaria | B12: 0.64599682 | C12: 0.35400318 | D12: 0.27 | E12: 1.1749813 | F12: 0.31739361 | G12: 0.0165 | H12: 0.64599682 | I12: 0.35400318 | J12: 0.27 | K12: 1.1749813 | L12: 0.31739361 | M12: 0.0165 | N12: 0.66787154 | O12: 0.33212846 | P12: 0.25 | Q12: 1.2048083 | R12: 0.27996249 | S12: 0.0162 | T12: 0.69330766 | U12: 0.30669234 | V12: 0.25 | W12: 1.1203262 | X12: 0.25213732 | Y12: 0.012055 | Z12: 0.65106515 | AA12: 0.34893485 | AB12: 0.25 | AC12: 0.9522674 | AD12: 0.40490891 | AE12: 0.0095
A13: Materiales de construcción | B13: 0.15787202 | C13: 0.84212798 | D13: 0.27 | E13: 1.1871343 | F13: 0.34535009 | G13: 0.0165 | H13: 0.15787202 | I13: 0.84212798 | J13: 0.27 | K13: 1.1871343 | L13: 0.34535009 | M13: 0.0165 | N13: 0.22436252 | O13: 0.77563748 | P13: 0.25 | Q13: 1.2772801 | R13: 0.29189914 | S13: 0.0162 | T13: 0.15361123 | U13: 0.84638877 | V13: 0.25 | W13: 1.3177985 | X13: 0.2871588 | Y13: 0.012055 | Z13: 0.15947308 | AA13: 0.84052692 | AB13: 0.25 | AC13: 1.3598827 | AD13: 0.34747493 | AE13: 0.0095
A14: Servicios para empresas y consumidores | B14: 0.18294499 | C14: 0.81705501 | D14: 0.27 | E14: 1.0891943 | F14: 0.41173437 | G14: 0.02068 | H14: 0.18294499 | I14: 0.81705501 | J14: 0.27 | K14: 1.0891943 | L14: 0.41173437 | M14: 0.02068 | N14: 0.21552516 | O14: 0.78447484 | P14: 0.25 | Q14: 1.17092 | R14: 0.45782494 | S14: 0.0162 | T14: 0.15210607 | U14: 0.84789393 | V14: 0.25 | W14: 1.0221017 | X14: 0.41290055 | Y14: 0.012055 | Z14: 0.14369516 | AA14: 0.85630484 | AB14: 0.25 | AC14: 1.00385 | AD14: 0.45393206 | AE14: 0.012
... A95: Mercado Total (sin el sector financiero) | B95: 0.16662687 | C95: 0.83337313 | D95: 0.27 | E95: 1.1485779 | F95: 0.44991556 | G95: 0.02068 | H95: 0.16662687 | I95: 0.83337313 | J95: 0.27 | K95: 1.1485779 | L95: 0.44991556 | M95: 0.02068 | N95: 0.20885367 | O95: 0.79114633 | P95: 0.25 | Q95: 1.292817 | R95: 0.47976813 | S95: 0.0162 | T95: 0.18433859 | U95: 0.81566141 | V95: 0.25 | W95: 1.0975226 | X95: 0.4700346 | Y95: 0.012055 | Z95: 0.16170905 | AA95: 0.83829095 | AB95: 0.25 | AC95: 1.0857817 | AD95: 0.57396285 | AE95: 0.012
B130: Cost of Debt Lookup Table (based on std dev in stock prices) | I130: Cost of Debt Lookup Table (based on std dev in stock prices) | P130: Cost of Debt Lookup Table (based on std dev in stock prices) | W130: Cost of Debt Lookup Table (based on std dev in stock prices) | AD130: Cost of Debt Lookup Table (based on std dev in stock prices)
A131: 2021 | B131: Standard Deviation | D131: Basis Spread | H131: 2022 | I131: Standard Deviation | K131: Basis Spread | O131: 2023 | P131: Standard Deviation | R131: Basis Spread | V131: 2024 | W131: Standard Deviation | Z131: Basis Spread | AC131: 2025 | AD131: Standard Deviation | AF131: Basis Spread
B132: 0 | C132: 0.25 | D132: 0.0099 | I132: 0 | J132: 0.25 | K132: 0.0099 | P132: 0 | Q132: 0.25 | R132: 0.0085 | W132: 0 | X132: 0.25 | Z132: 0.006243 | AD132: 0 | AF132: 0.005
B133: 0.25 | C133: 0.4 | D133: 0.0165 | I133: 0.25 | J133: 0.4 | K133: 0.0165 | P133: 0.250001 | Q133: 0.5 | R133: 0.0162 | W133: 0.250001 | X133: 0.5 | Z133: 0.012055 | AD133: 0.30001 | AF133: 0.0095
A134: Yes | B134: 0.4 | C134: 0.65 | D134: 0.02068 | H134: Yes | I134: 0.4 | J134: 0.65 | K134: 0.02068 | O134: Yes | P134: 0.500001 | Q134: 0.65 | R134: 0.02 | V134: Yes | W134: 0.500001 | X134: 0.65 | Z134: 0.014724 | AC134: Yes | AD134: 0.45001 | AF134: 0.012
A135: 0.27 | B135: 0.65 | C135: 0.75 | D135: 0.031625 | H135: 0.27 | I135: 0.65 | J135: 0.75 | K135: 0.031625 | O135: 0.25 | P135: 0.650001 | Q135: 0.8 | R135: 0.0313 | V135: 0.25 | W135: 0.650001 | X135: 0.8 | Z135: 0.022079 | AC135: 0.25 | AD135: 0.650001 | AF135: 0.0183
B136: 0.75 | C136: 0.9 | D136: 0.066125 | I136: 0.75 | J136: 0.9 | K136: 0.066125 | P136: 0.800001 | Q136: 0.9 | R136: 0.0526 | W136: 0.800001 | X136: 0.9 | Z136: 0.036056 | AD136: 0.800001 | AF136: 0.03
B137: 0.9 | C137: 1 | D137: 0.083375 | I137: 0.9 | J137: 1 | K137: 0.083375 | P137: 0.900001 | Q137: 1 | R137: 0.0737 | W137: 0.900001 | X137: 1 | Z137: 0.052404 | AD137: 0.900001 | AF137: 0.0442
B138: 1 | C138: 10 | D138: 0.100625 | I138: 1 | J138: 10 | K138: 0.100625 | P138: 1.000001 | Q138: 10 | R138: 0.1157 | W138: 1.000001 | X138: 10 | Z138: 0.0851 | AD138: 1.000001 | AF138: 0.0728

Sheet M. por conceptos
B2: MÉTODO POR CONCEPTOS
B4: 1. Proyección de cuentas
D6: =+AVERAGE(C9:D9) -> 7618983.5
B7: Ingresos | C7: =IFERROR('EE.FF Económicos'!D2,"") -> 2017 | D7: =IFERROR('EE.FF Económicos'!E2,"") -> 2018 | E7: =IFERROR('EE.FF Económicos'!F2,"") -> 2019 | F7: =IFERROR('EE.FF Económicos'!G2,"") -> 2020 | G7: =IFERROR('EE.FF Económicos'!H2,"") -> 2021 | H7: =G7+1 -> 2022 | I7: =H7+1 -> 2023 | J7: =I7+1 -> 2024 | K7: =J7+1 -> 2025 | L7: =K7+1 -> 2026 | M7: =L7+1 -> 2027 | N7: =M7+1 -> 2028 | O7: =N7+1 -> 2029 | ... V7: =U7+1 -> 2036
C8: =IFERROR('EE.FF Económicos'!D3,"") -> 1 | D8: =IFERROR('EE.FF Económicos'!E3,"") -> 2 | E8: =IFERROR('EE.FF Económicos'!F3,"") -> 3 | F8: =IFERROR('EE.FF Económicos'!G3,"") -> 4 | G8: =IFERROR('EE.FF Económicos'!H3,"") -> 5 | H8: =G8+1 -> 6 | I8: =H8+1 -> 7 | J8: =I8+1 -> 8 | K8: =J8+1 -> 9 | L8: =K8+1 -> 10 | M8: =L8+1 -> 11 | N8: =M8+1 -> 12 | O8: =N8+1 -> 13 | ... V8: =U8+1 -> 20
B9: Histórico | C9: =IF('EE.FF Económicos'!D35=0,"",'EE.FF Económicos'!D35) -> 6949265 | D9: =IF('EE.FF Económicos'!E35=0,"",'EE.FF Económicos'!E35) -> 8288702 | E9: =IF('EE.FF Económicos'!F35=0,"",'EE.FF Económicos'!F35) -> 9872187 | F9: =IF('EE.FF Económicos'!G35=0,"",'EE.FF Económicos'!G35) -> 10131767 | G9: =IF('EE.FF Económicos'!H35=0,"",'EE.FF Económicos'!H35) -> 12227663
B10: Promedio Móvil | D10: =IF(C9="","",AVERAGE(C9:D9)) -> 7618983.5 | E10: =IF(D9="","",AVERAGE(D9:E9)) -> 9080444.5 | F10: =IF(E9="","",AVERAGE(E9:F9)) -> 10001977 | G10: =IF(F9="","",AVERAGE(F9:G9)) -> 11179715
B11: Tendencia Logarítmica | G11: =LN(F8)*$E$16+$F$21 -> #REF! | H11: =LN(G8)*$E$16+$F$21 -> #REF! | I11: =LN(H8)*$E$16+$F$21 -> #REF! | J11: =LN(I8)*$E$16+$F$21 -> #REF! | K11: =LN(J8)*$E$16+$F$21 -> #REF! | L11: =LN(K8)*$E$16+$F$21 -> #REF! | M11: =LN(L8)*$E$16+$F$21 -> #REF! | N11: =LN(M8)*$E$16+$F$21 -> #REF! | ... V11: =LN(U8)*$E$16+$F$21 -> #REF!
B12: Tasa de crecimiento | H12: =IF(H11/G11-1>'EE.FF Económicos'!$D$53,H11/G11-1,'EE.FF Económicos'!$D$53) -> 0.015 | I12: =IF(I11/H11-1>'EE.FF Económicos'!$D$53,I11/H11-1,'EE.FF Económicos'!$D$53) -> 0.015 | J12: =IF(J11/I11-1>'EE.FF Económicos'!$D$53,J11/I11-1,'EE.FF Económicos'!$D$53) -> 0.015 | K12: =IF(K11/J11-1>'EE.FF Económicos'!$D$53,K11/J11-1,'EE.FF Económicos'!$D$53) -> 0.015 | L12: =IF(L11/K11-1>'EE.FF Económicos'!$D$53,L11/K11-1,'EE.FF Económicos'!$D$53) -> 0.015 | M12: =IF(M11/L11-1>'EE.FF Económicos'!$D$53,M11/L11-1,'EE.FF Económicos'!$D$53) -> 0.015 | N12: =IF(N11/M11-1>'EE.FF Económicos'!$D$53,N11/M11-1,'EE.FF Económicos'!$D$53) -> 0.015 | O12: =IF(O11/N11-1>'EE.FF Económicos'!$D$53,O11/N11-1,'EE.FF Económicos'!$D$53) -> 0.015 | ... V12: =IF(V11/U11-1>'EE.FF Económicos'!$D$53,V11/U11-1,'EE.FF Económicos'!$D$53) -> 0.015
B13: Proyección final | C13: =C9 -> 6949265 | D13: =D9 -> 8288702 | E13: =E9 -> 9872187 | F13: =F9 -> 10131767 | G13: =G9 -> 12227663 | H13: =G11*(1+H12) -> #REF! | I13: =H13*(1+I12) -> #REF! | J13: =I13*(1+J12) -> #REF! | K13: =J13*(1+K12) -> #REF! | L13: =K13*(1+L12) -> #REF! | M13: =L13*(1+M12) -> #REF! | N13: =M13*(1+N12) -> #REF! | O13: =N13*(1+O12) -> #REF! | P13: =O13*(1+P12) -> #REF! | ... V13: =U13*(1+V12) -> #REF!
E15: Pendiente | F15: Constante
E16: =INDEX(LINEST(INDEX(C10:G10,COUNTBLANK(C10:G10)+1):G10,LN(INDEX(C8:G8,COUNTBLANK(C10:G10)):INDEX(C8:G8,4)),TRUE,),1) -> #REF! | F16: =INDEX(LINEST(INDEX(C10:G10,COUNTBLANK(C10:G10)+1):G10,LN(INDEX(C8:G8,COUNTBLANK(C10:G10)):INDEX(C8:G8,4)),TRUE,),2) -> #REF!
E18: Ajuste de la constante
E19: Valor real | F19: =G10 -> 11179715
E20: Valor est. | F20: =LN(F8)*E16+F16 -> #REF!
E21: Const. Aj. | F21: =F19-F20+F16 -> #REF!
B24: Costo de ventas | C24: =C$7 -> 2017 | D24: =D$7 -> 2018 | E24: =E$7 -> 2019 | F24: =F$7 -> 2020 | G24: =G$7 -> 2021 | H24: =G24+1 -> 2022 | I24: =H24+1 -> 2023 | J24: =I24+1 -> 2024 | K24: =J24+1 -> 2025 | L24: =K24+1 -> 2026 | M24: =L24+1 -> 2027 | N24: =M24+1 -> 2028 | O24: =N24+1 -> 2029 | ... V24: =U24+1 -> 2036
C25: =C$8 -> 1 | D25: =D$8 -> 2 | E25: =E$8 -> 3 | F25: =F$8 -> 4 | G25: =G$8 -> 5 | H25: =G25+1 -> 6 | I25: =H25+1 -> 7 | J25: =I25+1 -> 8 | K25: =J25+1 -> 9 | L25: =K25+1 -> 10 | M25: =L25+1 -> 11 | N25: =M25+1 -> 12 | O25: =N25+1 -> 13 | ... V25: =U25+1 -> 20
B26: Histórico | C26: =IF('EE.FF Económicos'!D36=0,"",-'EE.FF Económicos'!D36) -> 5042402 | D26: =IF('EE.FF Económicos'!E36=0,"",-'EE.FF Económicos'!E36) -> 6244012 | E26: =IF('EE.FF Económicos'!F36=0,"",-'EE.FF Económicos'!F36) -> 7420013 | F26: =IF('EE.FF Económicos'!G36=0,"",-'EE.FF Económicos'!G36) -> 7712254 | G26: =IF('EE.FF Económicos'!H36=0,"",-'EE.FF Económicos'!H36) -> 9831454
B27: Promedio Móvil | D27: =IF(C26="","",AVERAGE(C26:D26)) -> 5643207 | E27: =IF(D26="","",AVERAGE(D26:E26)) -> 6832012.5 | F27: =IF(E26="","",AVERAGE(E26:F26)) -> 7566133.5 | G27: =IF(F26="","",AVERAGE(F26:G26)) -> 8771854
B28: Tendencia Logarítmica | G28: =LN(F25)*$E$33+$F$38 -> #REF! | H28: =LN(G25)*$E$33+$F$38 -> #REF! | I28: =LN(H25)*$E$33+$F$38 -> #REF! | J28: =LN(I25)*$E$33+$F$38 -> #REF! | K28: =LN(J25)*$E$33+$F$38 -> #REF! | L28: =LN(K25)*$E$33+$F$38 -> #REF! | M28: =LN(L25)*$E$33+$F$38 -> #REF! | N28: =LN(M25)*$E$33+$F$38 -> #REF! | ... V28: =LN(U25)*$E$33+$F$38 -> #REF!
B29: Tasa de crecimiento | H29: =IF(H$12>'EE.FF Económicos'!$D$53,H28/G28-1,'EE.FF Económicos'!$D$53) -> 0.015 | I29: =IF(I$12>'EE.FF Económicos'!$D$53,I28/H28-1,'EE.FF Económicos'!$D$53) -> 0.015 | J29: =IF(J$12>'EE.FF Económicos'!$D$53,J28/I28-1,'EE.FF Económicos'!$D$53) -> 0.015 | K29: =IF(K$12>'EE.FF Económicos'!$D$53,K28/J28-1,'EE.FF Económicos'!$D$53) -> 0.015 | L29: =IF(L$12>'EE.FF Económicos'!$D$53,L28/K28-1,'EE.FF Económicos'!$D$53) -> 0.015 | M29: =IF(M$12>'EE.FF Económicos'!$D$53,M28/L28-1,'EE.FF Económicos'!$D$53) -> 0.015 | N29: =IF(N$12>'EE.FF Económicos'!$D$53,N28/M28-1,'EE.FF Económicos'!$D$53) -> 0.015 | O29: =IF(O$12>'EE.FF Económicos'!$D$53,O28/N28-1,'EE.FF Económicos'!$D$53) -> 0.015 | ... V29: =IF(V$12>'EE.FF Económicos'!$D$53,V28/U28-1,'EE.FF Económicos'!$D$53) -> 0.015
B30: Proyección final | C30: =C26 -> 5042402 | D30: =D26 -> 6244012 | E30: =E26 -> 7420013 | F30: =F26 -> 7712254 | G30: =G26 -> 9831454 | H30: =G28*(1+H29) -> #REF! | I30: =H30*(1+I29) -> #REF! | J30: =I30*(1+J29) -> #REF! | K30: =J30*(1+K29) -> #REF! | L30: =K30*(1+L29) -> #REF! | M30: =L30*(1+M29) -> #REF! | N30: =M30*(1+N29) -> #REF! | O30: =N30*(1+O29) -> #REF! | P30: =O30*(1+P29) -> #REF! | ... V30: =U30*(1+V29) -> #REF!
E32: Pendiente | F32: Constante
E33: =INDEX(LINEST(INDEX(C27:G27,COUNTBLANK(C27:G27)+1):G27,LN(INDEX(C25:G25,COUNTBLANK(C27:G27)):INDEX(C25:G25,4)),TRUE,),1) -> #REF! | F33: =INDEX(LINEST(INDEX(C27:G27,COUNTBLANK(C27:G27)+1):G27,LN(INDEX(C25:G25,COUNTBLANK(C27:G27)):INDEX(C25:G25,4)),TRUE,),2) -> #REF!
E35: Ajuste de la constante
E36: Valor real | F36: =G27 -> 8771854
E37: Valor est. | F37: =LN(F25)*E33+F33 -> #REF!
E38: Const. Aj. | F38: =F36-F37+F33 -> #REF!
B42: Gasto de ventas | C42: =C$7 -> 2017 | D42: =D$7 -> 2018 | E42: =E$7 -> 2019 | F42: =F$7 -> 2020 | G42: =G$7 -> 2021 | H42: =G42+1 -> 2022 | I42: =H42+1 -> 2023 | J42: =I42+1 -> 2024 | K42: =J42+1 -> 2025 | L42: =K42+1 -> 2026 | M42: =L42+1 -> 2027 | N42: =M42+1 -> 2028 | O42: =N42+1 -> 2029 | ... V42: =U42+1 -> 2036
C43: =C$8 -> 1 | D43: =D$8 -> 2 | E43: =E$8 -> 3 | F43: =F$8 -> 4 | G43: =G$8 -> 5 | H43: =G43+1 -> 6 | I43: =H43+1 -> 7 | J43: =I43+1 -> 8 | K43: =J43+1 -> 9 | L43: =K43+1 -> 10 | M43: =L43+1 -> 11 | N43: =M43+1 -> 12 | O43: =N43+1 -> 13 | ... V43: =U43+1 -> 20
B44: Histórico | C44: =IF('EE.FF Económicos'!D38=0,"",-'EE.FF Económicos'!D38) -> 633605 | D44: =IF('EE.FF Económicos'!E38=0,"",-'EE.FF Económicos'!E38) -> 681336 | E44: =IF('EE.FF Económicos'!F38=0,"",-'EE.FF Económicos'!F38) -> 801905 | F44: =IF('EE.FF Económicos'!G38=0,"",-'EE.FF Económicos'!G38) -> 862157 | G44: =IF('EE.FF Económicos'!H38=0,"",-'EE.FF Económicos'!H38) -> 786246
B45: Promedio Móvil | D45: =IF(C44="","",AVERAGE(C44:D44)) -> 657470.5 | E45: =IF(D44="","",AVERAGE(D44:E44)) -> 741620.5 | F45: =IF(E44="","",AVERAGE(E44:F44)) -> 832031 | G45: =IF(F44="","",AVERAGE(F44:G44)) -> 824201.5
B46: Tendencia Logarítmica | G46: =LN(F43)*$E$51+$F$56 -> #REF! | H46: =LN(G43)*$E$51+$F$56 -> #REF! | I46: =LN(H43)*$E$51+$F$56 -> #REF! | J46: =LN(I43)*$E$51+$F$56 -> #REF! | K46: =LN(J43)*$E$51+$F$56 -> #REF! | L46: =LN(K43)*$E$51+$F$56 -> #REF! | M46: =LN(L43)*$E$51+$F$56 -> #REF! | N46: =LN(M43)*$E$51+$F$56 -> #REF! | ... V46: =LN(U43)*$E$51+$F$56 -> #REF!
B47: Tasa de crecimiento | H47: =IF(H$12>'EE.FF Económicos'!$D$53,H46/G46-1,'EE.FF Económicos'!$D$53) -> 0.015 | I47: =IF(I$12>'EE.FF Económicos'!$D$53,I46/H46-1,'EE.FF Económicos'!$D$53) -> 0.015 | J47: =IF(J$12>'EE.FF Económicos'!$D$53,J46/I46-1,'EE.FF Económicos'!$D$53) -> 0.015 | K47: =IF(K$12>'EE.FF Económicos'!$D$53,K46/J46-1,'EE.FF Económicos'!$D$53) -> 0.015 | L47: =IF(L$12>'EE.FF Económicos'!$D$53,L46/K46-1,'EE.FF Económicos'!$D$53) -> 0.015 | M47: =IF(M$12>'EE.FF Económicos'!$D$53,M46/L46-1,'EE.FF Económicos'!$D$53) -> 0.015 | N47: =IF(N$12>'EE.FF Económicos'!$D$53,N46/M46-1,'EE.FF Económicos'!$D$53) -> 0.015 | O47: =IF(O$12>'EE.FF Económicos'!$D$53,O46/N46-1,'EE.FF Económicos'!$D$53) -> 0.015 | ... V47: =IF(V$12>'EE.FF Económicos'!$D$53,V46/U46-1,'EE.FF Económicos'!$D$53) -> 0.015
B48: Proyección final | C48: =C44 -> 633605 | D48: =D44 -> 681336 | E48: =E44 -> 801905 | F48: =F44 -> 862157 | G48: =G44 -> 786246 | H48: =G46*(1+H47) -> #REF! | I48: =H48*(1+I47) -> #REF! | J48: =I48*(1+J47) -> #REF! | K48: =J48*(1+K47) -> #REF! | L48: =K48*(1+L47) -> #REF! | M48: =L48*(1+M47) -> #REF! | N48: =M48*(1+N47) -> #REF! | O48: =N48*(1+O47) -> #REF! | P48: =O48*(1+P47) -> #REF! | ... V48: =U48*(1+V47) -> #REF!
E50: Pendiente | F50: Constante
E51: =INDEX(LINEST(INDEX(C45:G45,COUNTBLANK(C45:G45)+1):G45,LN(INDEX(C43:G43,COUNTBLANK(C45:G45)):INDEX(C43:G43,4)),TRUE,),1) -> #REF! | F51: =INDEX(LINEST(INDEX(C45:G45,COUNTBLANK(C45:G45)+1):G45,LN(INDEX(C43:G43,COUNTBLANK(C45:G45)):INDEX(C43:G43,4)),TRUE,),2) -> #REF!
E53: Ajuste de la constante
E54: Valor real | F54: =G45 -> 824201.5
...

Sheet EE.FF Económicos
B2: N° | C2: BALANCE GENERAL | D2: =IFERROR(IF(E2>'Plantilla Usuario'!$C$7,E2-1,""),"") -> 2017 | E2: =IFERROR(IF(F2>'Plantilla Usuario'!$C$7,F2-1,""),"") -> 2018 | F2: =IFERROR(IF(G2>'Plantilla Usuario'!$C$7,G2-1,""),"") -> 2019 | G2: =IFERROR(IF(H2>'Plantilla Usuario'!$C$7,H2-1,""),"") -> 2020 | H2: ='Plantilla Usuario'!C8 -> 2021
B3: 1 | D3: =IFERROR(IF(E3-1<1,"",E3-1),"") -> 1 | E3: =IFERROR(IF(F3-1<1,"",F3-1),"") -> 2 | F3: =IFERROR(IF(G3-1<1,"",G3-1),"") -> 3 | G3: =IFERROR(IF(H3-1<1,"",H3-1),"") -> 4 | H3: =5-COUNTBLANK(D2:H2) -> 5
B4: 2 | C4: Efectivo y Equivalentes al Efectivo | D4: =IF('EE.FF Económicos'!$D$54="Soles",HLOOKUP(D$2,'Plantilla Usuario'!$B$10:$I$54,$B4),HLOOKUP(D$2,'Plantilla Usuario'!$B$10:$I$54,$B4)/VLOOKUP($H$2,Tablas!$B$52:$C$59,2)) -> 3289719 | E4: =IF('EE.FF Económicos'!$D$54="Soles",HLOOKUP(E$2,'Plantilla Usuario'!$B$10:$I$54,$B4),HLOOKUP(E$2,'Plantilla Usuario'!$B$10:$I$54,$B4)/VLOOKUP($H$2,Tablas!$B$52:$C$59,2)) -> 4103986 | F4: =IF('EE.FF Económicos'!$D$54="Soles",HLOOKUP(F$2,'Plantilla Usuario'!$B$10:$I$54,$B4),HLOOKUP(F$2,'Plantilla Usuario'!$B$10:$I$54,$B4)/VLOOKUP($H$2,Tablas!$B$52:$C$59,2)) -> 4490817 | G4: =IF('EE.FF Económicos'!$D$54="Soles",HLOOKUP(G$2,'Plantilla Usuario'!$B$10:$I$54,$B4),HLOOKUP(G$2,'Plantilla Usuario'!$B$10:$I$54,$B4)/VLOOKUP($H$2,Tablas!$B$52:$C$59,2)) -> 4618768 | H4: =IF('EE.FF Económicos'!$D$54="Soles",HLOOKUP(H$2,'Plantilla Usuario'!$B$10:$I$54,$B4),HLOOKUP(H$2,'Plantilla Usuario'!$B$10:$I$54,$B4)/VLOOKUP($H$2,Tablas!$B$52:$C$59,2)) -> 6509850
B5: 3 | C5: Cuentas por Cobrar Comerciales y Otras Cuentas por Cobrar | D5: =IF('EE.FF Económicos'!$D$54="Soles",HLOOKUP(D$2,'Plantilla Usuario'!$B$10:$I$54,$B5),HLOOKUP(D$2,'Plantilla Usuario'!$B$10:$I$54,$B5)/VLOOKUP($H$2,Tablas!$B$52:$C$59,2)) -> 0 | E5: =IF('EE.FF Económicos'!$D$54="Soles",HLOOKUP(E$2,'Plantilla Usuario'!$B$10:$I$54,$B5),HLOOKUP(E$2,'Plantilla Usuario'!$B$10:$I$54,$B5)/VLOOKUP($H$2,Tablas!$B$52:$C$59,2)) -> 0 | F5: =IF('EE.FF Económicos'!$D$54="Soles",HLOOKUP(F$2,'Plantilla Usuario'!$B$10:$I$54,$B5),HLOOKUP(F$2,'Plantilla Usuario'!$B$10:$I$54,$B5)/VLOOKUP($H$2,Tablas!$B$52:$C$59,2)) -> 0 | G5: =IF('EE.FF Económicos'!$D$54="Soles",HLOOKUP(G$2,'Plantilla Usuario'!$B$10:$I$54,$B5),HLOOKUP(G$2,'Plantilla Usuario'!$B$10:$I$54,$B5)/VLOOKUP($H$2,Tablas!$B$52:$C$59,2)) -> 0 | H5: =IF('EE.FF Económicos'!$D$54="Soles",HLOOKUP(H$2,'Plantilla Usuario'!$B$10:$I$54,$B5),HLOOKUP(H$2,'Plantilla Usuario'!$B$10:$I$54,$B5)/VLOOKUP($H$2,Tablas!$B$52:$C$59,2)) -> 0
B6: 4 | C6: Inventarios | D6: =IF('EE.FF Económicos'!$D$54="Soles",HLOOKUP(D$2,'Plantilla Usuario'!$B$10:$I$54,$B6),HLOOKUP(D$2,'Plantilla Usuario'!$B$10:$I$54,$B6)/VLOOKUP($H$2,Tablas!$B$52:$C$59,2)) -> 0 | E6: =IF('EE.FF Económicos'!$D$54="Soles",HLOOKUP(E$2,'Plantilla Usuario'!$B$10:$I$54,$B6),HLOOKUP(E$2,'Plantilla Usuario'!$B$10:$I$54,$B6)/VLOOKUP($H$2,Tablas!$B$52:$C$59,2)) -> 0 | F6: =IF('EE.FF Económicos'!$D$54="Soles",HLOOKUP(F$2,'Plantilla Usuario'!$B$10:$I$54,$B6),HLOOKUP(F$2,'Plantilla Usuario'!$B$10:$I$54,$B6)/VLOOKUP($H$2,Tablas!$B$52:$C$59,2)) -> 0 | G6: =IF('EE.FF Económicos'!$D$54="Soles",HLOOKUP(G$2,'Plantilla Usuario'!$B$10:$I$54,$B6),HLOOKUP(G$2,'Plantilla Usuario'!$B$10:$I$54,$B6)/VLOOKUP($H$2,Tablas!$B$52:$C$59,2)) -> 0 | H6: =IF('EE.FF Económicos'!$D$54="Soles",HLOOKUP(H$2,'Plantilla Usuario'!$B$10:$I$54,$B6),HLOOKUP(H$2,'Plantilla Usuario'!$B$10:$I$54,$B6)/VLOOKUP($H$2,Tablas!$B$52:$C$59,2)) -> 0
B7: 5 | C7: Otros activos no financieros | D7: =IF('EE.FF Económicos'!$D$54="Soles",HLOOKUP(D$2,'Plantilla Usuario'!$B$10:$I$54,$B7),HLOOKUP(D$2,'Plantilla Usuario'!$B$10:$I$54,$B7)/VLOOKUP($H$2,Tablas!$B$52:$C$59,2)) -> 0 | E7: =IF('EE.FF Económicos'!$D$54="Soles",HLOOKUP(E$2,'Plantilla Usuario'!$B$10:$I$54,$B7),HLOOKUP(E$2,'Plantilla Usuario'!$B$10:$I$54,$B7)/VLOOKUP($H$2,Tablas!$B$52:$C$59,2)) -> 0 | F7: =IF('EE.FF Económicos'!$D$54="Soles",HLOOKUP(F$2,'Plantilla Usuario'!$B$10:$I$54,$B7),HLOOKUP(F$2,'Plantilla Usuario'!$B$10:$I$54,$B7)/VLOOKUP($H$2,Tablas!$B$52:$C$59,2)) -> 0 | G7: =IF('EE.FF Económicos'!$D$54="Soles",HLOOKUP(G$2,'Plantilla Usuario'!$B$10:$I$54,$B7),HLOOKUP(G$2,'Plantilla Usuario'!$B$10:$I$54,$B7)/VLOOKUP($H$2,Tablas!$B$52:$C$59,2)) -> 0 | H7: =IF('EE.FF Económicos'!$D$54="Soles",HLOOKUP(H$2,'Plantilla Usuario'!$B$10:$I$54,$B7),HLOOKUP(H$2,'Plantilla Usuario'!$B$10:$I$54,$B7)/VLOOKUP($H$2,Tablas!$B$52:$C$59,2)) -> 0
B8: 6 | C8: Total Activos Corrientes | D8: =IF('EE.FF Económicos'!$D$54="Soles",HLOOKUP(D$2,'Plantilla Usuario'!$B$10:$I$54,$B8),HLOOKUP(D$2,'Plantilla Usuario'!$B$10:$I$54,$B8)/VLOOKUP($H$2,Tablas!$B$52:$C$59,2)) -> 3289719 | E8: =IF('EE.FF Económicos'!$D$54="Soles",HLOOKUP(E$2,'Plantilla Usuario'!$B$10:$I$54,$B8),HLOOKUP(E$2,'Plantilla Usuario'!$B$10:$I$54,$B8)/VLOOKUP($H$2,Tablas!$B$52:$C$59,2)) -> 4103986 | F8: =IF('EE.FF Económicos'!$D$54="Soles",HLOOKUP(F$2,'Plantilla Usuario'!$B$10:$I$54,$B8),HLOOKUP(F$2,'Plantilla Usuario'!$B$10:$I$54,$B8)/VLOOKUP($H$2,Tablas!$B$52:$C$59,2)) -> 4490817 | G8: =IF('EE.FF Económicos'!$D$54="Soles",HLOOKUP(G$2,'Plantilla Usuario'!$B$10:$I$54,$B8),HLOOKUP(G$2,'Plantilla Usuario'!$B$10:$I$54,$B8)/VLOOKUP($H$2,Tablas!$B$52:$C$59,2)) -> 4618768 | H8: =IF('EE.FF Económicos'!$D$54="Soles",HLOOKUP(H$2,'Plantilla Usuario'!$B$10:$I$54,$B8),HLOOKUP(H$2,'Plantilla Usuario'!$B$10:$I$54,$B8)/VLOOKUP($H$2,Tablas!$B$52:$C$59,2)) -> 6509850
B9: 7 | C9: Cuentas por Cobrar Comerciales y Otras Cuentas por Cobrar | D9: =IF('EE.FF Económicos'!$D$54="Soles",HLOOKUP(D$2,'Plantilla Usuario'!$B$10:$I$54,$B9),HLOOKUP(D$2,'Plantilla Usuario'!$B$10:$I$54,$B9)/VLOOKUP($H$2,Tablas!$B$52:$C$59,2)) -> 3826276 | E9: =IF('EE.FF Económicos'!$D$54="Soles",HLOOKUP(E$2,'Plantilla Usuario'!$B$10:$I$54,$B9),HLOOKUP(E$2,'Plantilla Usuario'!$B$10:$I$54,$B9)/VLOOKUP($H$2,Tablas!$B$52:$C$59,2)) -> 4955240 | F9: =IF('EE.FF Económicos'!$D$54="Soles",HLOOKUP(F$2,'Plantilla Usuario'!$B$10:$I$54,$B9),HLOOKUP(F$2,'Plantilla Usuario'!$B$10:$I$54,$B9)/VLOOKUP($H$2,Tablas!$B$52:$C$59,2)) -> 6751464 | G9: =IF('EE.FF Económicos'!$D$54="Soles",HLOOKUP(G$2,'Plantilla Usuario'!$B$10:$I$54,$B9),HLOOKUP(G$2,'Plantilla Usuario'!$B$10:$I$54,$B9)/VLOOKUP($H$2,Tablas!$B$52:$C$59,2)) -> 7031343 | H9: =IF('EE.FF Económicos'!$D$54="Soles",HLOOKUP(H$2,'Plantilla Usuario'!$B$10:$I$54,$B9),HLOOKUP(H$2,'Plantilla Usuario'!$B$10:$I$54,$B9)/VLOOKUP($H$2,Tablas!$B$52:$C$59,2)) -> 6898453
B10: 8 | C10: Inversiones Financieras e inmobiliarias | D10: =IF('EE.FF Económicos'!$D$54="Soles",HLOOKUP(D$2,'Plantilla Usuario'!$B$10:$I$54,$B10),HLOOKUP(D$2,'Plantilla Usuario'!$B$10:$I$54,$B10)/VLOOKUP($H$2,Tablas!$B$52:$C$59,2)) -> 0 | E10: =IF('EE.FF Económicos'!$D$54="Soles",HLOOKUP(E$2,'Plantilla Usuario'!$B$10:$I$54,$B10),HLOOKUP(E$2,'Plantilla Usuario'!$B$10:$I$54,$B10)/VLOOKUP($H$2,Tablas!$B$52:$C$59,2)) -> 0 | F10: =IF('EE.FF Económicos'!$D$54="Soles",HLOOKUP(F$2,'Plantilla Usuario'!$B$10:$I$54,$B10),HLOOKUP(F$2,'Plantilla Usuario'!$B$10:$I$54,$B10)/VLOOKUP($H$2,Tablas!$B$52:$C$59,2)) -> 0 | G10: =IF('EE.FF Económicos'!$D$54="Soles",HLOOKUP(G$2,'Plantilla Usuario'!$B$10:$I$54,$B10),HLOOKUP(G$2,'Plantilla Usuario'!$B$10:$I$54,$B10)/VLOOKUP($H$2,Tablas!$B$52:$C$59,2)) -> 0 | H10: =IF('EE.FF Económicos'!$D$54="Soles",HLOOKUP(H$2,'Plantilla Usuario'!$B$10:$I$54,$B10),HLOOKUP(H$2,'Plantilla Usuario'!$B$10:$I$54,$B10)/VLOOKUP($H$2,Tablas!$B$52:$C$59,2)) -> 0
B11: 9 | C11: Propiedades, Planta y Equipo | D11: =IF('EE.FF Económicos'!$D$54="Soles",HLOOKUP(D$2,'Plantilla Usuario'!$B$10:$I$54,$B11),HLOOKUP(D$2,'Plantilla Usuario'!$B$10:$I$54,$B11)/VLOOKUP($H$2,Tablas!$B$52:$C$59,2)) -> 1865624 | E11: =IF('EE.FF Económicos'!$D$54="Soles",HLOOKUP(E$2,'Plantilla Usuario'!$B$10:$I$54,$B11),HLOOKUP(E$2,'Plantilla Usuario'!$B$10:$I$54,$B11)/VLOOKUP($H$2,Tablas!$B$52:$C$59,2)) -> 2537852 | F11: =IF('EE.FF Económicos'!$D$54="Soles",HLOOKUP(F$2,'Plantilla Usuario'!$B$10:$I$54,$B11),HLOOKUP(F$2,'Plantilla Usuario'!$B$10:$I$54,$B11)/VLOOKUP($H$2,Tablas!$B$52:$C$59,2)) -> 3323015 | G11: =IF('EE.FF Económicos'!$D$54="Soles",HLOOKUP(G$2,'Plantilla Usuario'!$B$10:$I$54,$B11),HLOOKUP(G$2,'Plantilla Usuario'!$B$10:$I$54,$B11)/VLOOKUP($H$2,Tablas!$B$52:$C$59,2)) -> 3410774 | H11: =IF('EE.FF Económicos'!$D$54="Soles",HLOOKUP(H$2,'Plantilla Usuario'!$B$10:$I$54,$B11),HLOOKUP(H$2,'Plantilla Usuario'!$B$10:$I$54,$B11)/VLOOKUP($H$2,Tablas!$B$52:$C$59,2)) -> 3343589
B12: 10 | C12: Depreciación Acumulada | D12: =IF('EE.FF Económicos'!$D$54="Soles",HLOOKUP(D$2,'Plantilla Usuario'!$B$10:$I$54,$B12),HLOOKUP(D$2,'Plantilla Usuario'!$B$10:$I$54,$B12)/VLOOKUP($H$2,Tablas!$B$52:$C$59,2)) -> 1198090 | E12: =IF('EE.FF Económicos'!$D$54="Soles",HLOOKUP(E$2,'Plantilla Usuario'!$B$10:$I$54,$B12),HLOOKUP(E$2,'Plantilla Usuario'!$B$10:$I$54,$B12)/VLOOKUP($H$2,Tablas!$B$52:$C$59,2)) -> 1361126 | F12: =IF('EE.FF Económicos'!$D$54="Soles",HLOOKUP(F$2,'Plantilla Usuario'!$B$10:$I$54,$B12),HLOOKUP(F$2,'Plantilla Usuario'!$B$10:$I$54,$B12)/VLOOKUP($H$2,Tablas!$B$52:$C$59,2)) -> 1540298 | G12: =IF('EE.FF Económicos'!$D$54="Soles",HLOOKUP(G$2,'Plantilla Usuario'!$B$10:$I$54,$B12),HLOOKUP(G$2,'Plantilla Usuario'!$B$10:$I$54,$B12)/VLOOKUP($H$2,Tablas!$B$52:$C$59,2)) -> 1801309 | H12: =IF('EE.FF Económicos'!$D$54="Soles",HLOOKUP(H$2,'Plantilla Usuario'!$B$10:$I$54,$B12),HLOOKUP(H$2,'Plantilla Usuario'!$B$10:$I$54,$B12)/VLOOKUP($H$2,Tablas!$B$52:$C$59,2)) -> 1973854
B13: 11 | C13: Activos Intangibles | D13: =IF('EE.FF Económicos'!$D$54="Soles",HLOOKUP(D$2,'Plantilla Usuario'!$B$10:$I$54,$B13),HLOOKUP(D$2,'Plantilla Usuario'!$B$10:$I$54,$B13)/VLOOKUP($H$2,Tablas!$B$52:$C$59,2)) -> 0 | E13: =IF('EE.FF Económicos'!$D$54="Soles",HLOOKUP(E$2,'Plantilla Usuario'!$B$10:$I$54,$B13),HLOOKUP(E$2,'Plantilla Usuario'!$B$10:$I$54,$B13)/VLOOKUP($H$2,Tablas!$B$52:$C$59,2)) -> 0 | F13: =IF('EE.FF Económicos'!$D$54="Soles",HLOOKUP(F$2,'Plantilla Usuario'!$B$10:$I$54,$B13),HLOOKUP(F$2,'Plantilla Usuario'!$B$10:$I$54,$B13)/VLOOKUP($H$2,Tablas!$B$52:$C$59,2)) -> 0 | G13: =IF('EE.FF Económicos'!$D$54="Soles",HLOOKUP(G$2,'Plantilla Usuario'!$B$10:$I$54,$B13),HLOOKUP(G$2,'Plantilla Usuario'!$B$10:$I$54,$B13)/VLOOKUP($H$2,Tablas!$B$52:$C$59,2)) -> 0 | H13: =IF('EE.FF Económicos'!$D$54="Soles",HLOOKUP(H$2,'Plantilla Usuario'!$B$10:$I$54,$B13),HLOOKUP(H$2,'Plantilla Usuario'!$B$10:$I$54,$B13)/VLOOKUP($H$2,Tablas!$B$52:$C$59,2)) -> 0
B14: 12 | C14: Otros activos no financieros | D14: =IF('EE.FF Económicos'!$D$54="Soles",HLOOKUP(D$2,'Plantilla Usuario'!$B$10:$I$54,$B14),HLOOKUP(D$2,'Plantilla Usuario'!$B$10:$I$54,$B14)/VLOOKUP($H$2,Tablas!$B$52:$C$59,2)) -> 0 | E14: =IF('EE.FF Económicos'!$D$54="Soles",HLOOKUP(E$2,'Plantilla Usuario'!$B$10:$I$54,$B14),HLOOKUP(E$2,'Plantilla Usuario'!$B$10:$I$54,$B14)/VLOOKUP($H$2,Tablas!$B$52:$C$59,2)) -> 0 | F14: =IF('EE.FF Económicos'!$D$54="Soles",HLOOKUP(F$2,'Plantilla Usuario'!$B$10:$I$54,$B14),HLOOKUP(F$2,'Plantilla Usuario'!$B$10:$I$54,$B14)/VLOOKUP($H$2,Tablas!$B$52:$C$59,2)) -> 0 | G14: =IF('EE.FF Económicos'!$D$54="Soles",HLOOKUP(G$2,'Plantilla Usuario'!$B$10:$I$54,$B14),HLOOKUP(G$2,'Plantilla Usuario'!$B$10:$I$54,$B14)/VLOOKUP($H$2,Tablas!$B$52:$C$59,2)) -> 0 | H14: =IF('EE.FF Económicos'!$D$54="Soles",HLOOKUP(H$2,'Plantilla Usuario'!$B$10:$I$54,$B14),HLOOKUP(H$2,'Plantilla Usuario'!$B$10:$I$54,$B14)/VLOOKUP($H$2,Tablas!$B$52:$C$59,2)) -> 0
B15: 13 | C15: Total Activos No Corrientes | D15: =IF('EE.FF Económicos'!$D$54="Soles",HLOOKUP(D$2,'Plantilla Usuario'!$B$10:$I$54,$B15),HLOOKUP(D$2,'Plantilla Usuario'!$B$10:$I$54,$B15)/VLOOKUP($H$2,Tablas!$B$52:$C$59,2)) -> 3826276 | E15: =IF('EE.FF Económicos'!$D$54="Soles",HLOOKUP(E$2,'Plantilla Usuario'!$B$10:$I$54,$B15),HLOOKUP(E$2,'Plantilla Usuario'!$B$10:$I$54,$B15)/VLOOKUP($H$2,Tablas!$B$52:$C$59,2)) -> 4955240 | F15: =IF('EE.FF Económicos'!$D$54="Soles",HLOOKUP(F$2,'Plantilla Usuario'!$B$10:$I$54,$B15),HLOOKUP(F$2,'Plantilla Usuario'!$B$10:$I$54,$B15)/VLOOKUP($H$2,Tablas!$B$52:$C$59,2)) -> 6751464 | G15: =IF('EE.FF Económicos'!$D$54="Soles",HLOOKUP(G$2,'Plantilla Usuario'!$B$10:$I$54,$B15),HLOOKUP(G$2,'Plantilla Usuario'!$B$10:$I$54,$B15)/VLOOKUP($H$2,Tablas!$B$52:$C$59,2)) -> 7031343 | H15: =IF('EE.FF Económicos'!$D$54="Soles",HLOOKUP(H$2,'Plantilla Usuario'!$B$10:$I$54,$B15),HLOOKUP(H$2,'Plantilla Usuario'!$B$10:$I$54,$B15)/VLOOKUP($H$2,Tablas!$B$52:$C$59,2)) -> 6898453
... B31: 29 | C31: TOTAL PASIVOS Y PATRIMONIO | D31: =IF('EE.FF Económicos'!$D$54="Soles",HLOOKUP(D$2,'Plantilla Usuario'!$B$10:$I$54,$B31),HLOOKUP(D$2,'Plantilla Usuario'!$B$10:$I$54,$B31)/VLOOKUP($H$2,Tablas!$B$52:$C$59,2)) -> 7115995 | E31: =IF('EE.FF Económicos'!$D$54="Soles",HLOOKUP(E$2,'Plantilla Usuario'!$B$10:$I$54,$B31),HLOOKUP(E$2,'Plantilla Usuario'!$B$10:$I$54,$B31)/VLOOKUP($H$2,Tablas!$B$52:$C$59,2)) -> 9059226 | F31: =IF('EE.FF Económicos'!$D$54="Soles",HLOOKUP(F$2,'Plantilla Usuario'!$B$10:$I$54,$B31),HLOOKUP(F$2,'Plantilla Usuario'!$B$10:$I$54,$B31)/VLOOKUP($H$2,Tablas!$B$52:$C$59,2)) -> 11242281 | G31: =IF('EE.FF Económicos'!$D$54="Soles",HLOOKUP(G$2,'Plantilla Usuario'!$B$10:$I$54,$B31),HLOOKUP(G$2,'Plantilla Usuario'!$B$10:$I$54,$B31)/VLOOKUP($H$2,Tablas!$B$52:$C$59,2)) -> 11650111 | H31: =IF('EE.FF Económicos'!$D$54="Soles",HLOOKUP(H$2,'Plantilla Usuario'!$B$10:$I$54,$B31),HLOOKUP(H$2,'Plantilla Usuario'!$B$10:$I$54,$B31)/VLOOKUP($H$2,Tablas!$B$52:$C$59,2)) -> 13408303
B32: 30
B33: 31
B34: 32 | C34: ESTADO DE RESULTADOS | D34: =D2 -> 2017 | E34: =E2 -> 2018 | F34: =F2 -> 2019 | G34: =G2 -> 2020 | H34: =H2 -> 2021
B35: 33 | C35: Ingresos de Actividades Ordinarias | D35: =VALUE(IF('EE.FF Económicos'!$D$54="Soles",HLOOKUP(D$2,'Plantilla Usuario'!$B$10:$I$54,$B35),HLOOKUP(D$2,'Plantilla Usuario'!$B$10:$I$54,$B35)/VLOOKUP($H$2,Tablas!$B$52:$C$59,2))) -> 6949265 | E35: =VALUE(IF('EE.FF Económicos'!$D$54="Soles",HLOOKUP(E$2,'Plantilla Usuario'!$B$10:$I$54,$B35),HLOOKUP(E$2,'Plantilla Usuario'!$B$10:$I$54,$B35)/VLOOKUP($H$2,Tablas!$B$52:$C$59,2))) -> 8288702 | F35: =VALUE(IF('EE.FF Económicos'!$D$54="Soles",HLOOKUP(F$2,'Plantilla Usuario'!$B$10:$I$54,$B35),HLOOKUP(F$2,'Plantilla Usuario'!$B$10:$I$54,$B35)/VLOOKUP($H$2,Tablas!$B$52:$C$59,2))) -> 9872187 | G35: =VALUE(IF('EE.FF Económicos'!$D$54="Soles",HLOOKUP(G$2,'Plantilla Usuario'!$B$10:$I$54,$B35),HLOOKUP(G$2,'Plantilla Usuario'!$B$10:$I$54,$B35)/VLOOKUP($H$2,Tablas!$B$52:$C$59,2))) -> 10131767 | H35: =VALUE(IF('EE.FF Económicos'!$D$54="Soles",HLOOKUP(H$2,'Plantilla Usuario'!$B$10:$I$54,$B35),HLOOKUP(H$2,'Plantilla Usuario'!$B$10:$I$54,$B35)/VLOOKUP($H$2,Tablas!$B$52:$C$59,2))) -> 12227663
B36: 34 | C36: Costo de Ventas | D36: =IF('EE.FF Económicos'!$D$54="Soles",HLOOKUP(D$2,'Plantilla Usuario'!$B$10:$I$54,$B36),HLOOKUP(D$2,'Plantilla Usuario'!$B$10:$I$54,$B36)/VLOOKUP($H$2,Tablas!$B$52:$C$59,2)) -> -5042402 | E36: =IF('EE.FF Económicos'!$D$54="Soles",HLOOKUP(E$2,'Plantilla Usuario'!$B$10:$I$54,$B36),HLOOKUP(E$2,'Plantilla Usuario'!$B$10:$I$54,$B36)/VLOOKUP($H$2,Tablas!$B$52:$C$59,2)) -> -6244012 | F36: =IF('EE.FF Económicos'!$D$54="Soles",HLOOKUP(F$2,'Plantilla Usuario'!$B$10:$I$54,$B36),HLOOKUP(F$2,'Plantilla Usuario'!$B$10:$I$54,$B36)/VLOOKUP($H$2,Tablas!$B$52:$C$59,2)) -> -7420013 | G36: =IF('EE.FF Económicos'!$D$54="Soles",HLOOKUP(G$2,'Plantilla Usuario'!$B$10:$I$54,$B36),HLOOKUP(G$2,'Plantilla Usuario'!$B$10:$I$54,$B36)/VLOOKUP($H$2,Tablas!$B$52:$C$59,2)) -> -7712254 | H36: =IF('EE.FF Económicos'!$D$54="Soles",HLOOKUP(H$2,'Plantilla Usuario'!$B$10:$I$54,$B36),HLOOKUP(H$2,'Plantilla Usuario'!$B$10:$I$54,$B36)/VLOOKUP($H$2,Tablas!$B$52:$C$59,2)) -> -9831454
B37: 35 | C37: Utilidad Bruta | D37: =IF('EE.FF Económicos'!$D$54="Soles",HLOOKUP(D$2,'Plantilla Usuario'!$B$10:$I$54,$B37),HLOOKUP(D$2,'Plantilla Usuario'!$B$10:$I$54,$B37)/VLOOKUP($H$2,Tablas!$B$52:$C$59,2)) -> 1906863 | E37: =IF('EE.FF Económicos'!$D$54="Soles",HLOOKUP(E$2,'Plantilla Usuario'!$B$10:$I$54,$B37),HLOOKUP(E$2,'Plantilla Usuario'!$B$10:$I$54,$B37)/VLOOKUP($H$2,Tablas!$B$52:$C$59,2)) -> 2044690 | F37: =IF('EE.FF Económicos'!$D$54="Soles",HLOOKUP(F$2,'Plantilla Usuario'!$B$10:$I$54,$B37),HLOOKUP(F$2,'Plantilla Usuario'!$B$10:$I$54,$B37)/VLOOKUP($H$2,Tablas!$B$52:$C$59,2)) -> 2452174 | G37: =IF('EE.FF Económicos'!$D$54="Soles",HLOOKUP(G$2,'Plantilla Usuario'!$B$10:$I$54,$B37),HLOOKUP(G$2,'Plantilla Usuario'!$B$10:$I$54,$B37)/VLOOKUP($H$2,Tablas!$B$52:$C$59,2)) -> 2419513 | H37: =IF('EE.FF Económicos'!$D$54="Soles",HLOOKUP(H$2,'Plantilla Usuario'!$B$10:$I$54,$B37),HLOOKUP(H$2,'Plantilla Usuario'!$B$10:$I$54,$B37)/VLOOKUP($H$2,Tablas!$B$52:$C$59,2)) -> 2396209
B38: 36 | C38: Gastos de Ventas y Distribución | D38: =IF('EE.FF Económicos'!$D$54="Soles",HLOOKUP(D$2,'Plantilla Usuario'!$B$10:$I$54,$B38),HLOOKUP(D$2,'Plantilla Usuario'!$B$10:$I$54,$B38)/VLOOKUP($H$2,Tablas!$B$52:$C$59,2)) -> -633605 | E38: =IF('EE.FF Económicos'!$D$54="Soles",HLOOKUP(E$2,'Plantilla Usuario'!$B$10:$I$54,$B38),HLOOKUP(E$2,'Plantilla Usuario'!$B$10:$I$54,$B38)/VLOOKUP($H$2,Tablas!$B$52:$C$59,2)) -> -681336 | F38: =IF('EE.FF Económicos'!$D$54="Soles",HLOOKUP(F$2,'Plantilla Usuario'!$B$10:$I$54,$B38),HLOOKUP(F$2,'Plantilla Usuario'!$B$10:$I$54,$B38)/VLOOKUP($H$2,Tablas!$B$52:$C$59,2)) -> -801905 | G38: =IF('EE.FF Económicos'!$D$54="Soles",HLOOKUP(G$2,'Plantilla Usuario'!$B$10:$I$54,$B38),HLOOKUP(G$2,'Plantilla Usuario'!$B$10:$I$54,$B38)/VLOOKUP($H$2,Tablas!$B$52:$C$59,2)) -> -862157 | H38: =IF('EE.FF Económicos'!$D$54="Soles",HLOOKUP(H$2,'Plantilla Usuario'!$B$10:$I$54,$B38),HLOOKUP(H$2,'Plantilla Usuario'!$B$10:$I$54,$B38)/VLOOKUP($H$2,Tablas!$B$52:$C$59,2)) -> -786246
B39: 37 | C39: Gastos de Administración | D39: =IF('EE.FF Económicos'!$D$54="Soles",HLOOKUP(D$2,'Plantilla Usuario'!$B$10:$I$54,$B40),HLOOKUP(D$2,'Plantilla Usuario'!$B$10:$I$54,$B40)/VLOOKUP($H$2,Tablas!$B$52:$C$59,2)) -> -487579 | E39: =IF('EE.FF Económicos'!$D$54="Soles",HLOOKUP(E$2,'Plantilla Usuario'!$B$10:$I$54,$B40),HLOOKUP(E$2,'Plantilla Usuario'!$B$10:$I$54,$B40)/VLOOKUP($H$2,Tablas!$B$52:$C$59,2)) -> -603139 | F39: =IF('EE.FF Económicos'!$D$54="Soles",HLOOKUP(F$2,'Plantilla Usuario'!$B$10:$I$54,$B40),HLOOKUP(F$2,'Plantilla Usuario'!$B$10:$I$54,$B40)/VLOOKUP($H$2,Tablas!$B$52:$C$59,2)) -> -651838 | G39: =IF('EE.FF Económicos'!$D$54="Soles",HLOOKUP(G$2,'Plantilla Usuario'!$B$10:$I$54,$B40),HLOOKUP(G$2,'Plantilla Usuario'!$B$10:$I$54,$B40)/VLOOKUP($H$2,Tablas!$B$52:$C$59,2)) -> -688428 | H39: =IF('EE.FF Económicos'!$D$54="Soles",HLOOKUP(H$2,'Plantilla Usuario'!$B$10:$I$54,$B40),HLOOKUP(H$2,'Plantilla Usuario'!$B$10:$I$54,$B40)/VLOOKUP($H$2,Tablas!$B$52:$C$59,2)) -> -732928
B40: 38 | C40: Otros ingresos (gastos) netos | D40: =IF('EE.FF Económicos'!$D$54="Soles",HLOOKUP(D$2,'Plantilla Usuario'!$B$10:$I$54,$B41),HLOOKUP(D$2,'Plantilla Usuario'!$B$10:$I$54,$B41)/VLOOKUP($H$2,Tablas!$B$52:$C$59,2)) -> -42607 | E40: =IF('EE.FF Económicos'!$D$54="Soles",HLOOKUP(E$2,'Plantilla Usuario'!$B$10:$I$54,$B41),HLOOKUP(E$2,'Plantilla Usuario'!$B$10:$I$54,$B41)/VLOOKUP($H$2,Tablas!$B$52:$C$59,2)) -> 26059 | F40: =IF('EE.FF Económicos'!$D$54="Soles",HLOOKUP(F$2,'Plantilla Usuario'!$B$10:$I$54,$B41),HLOOKUP(F$2,'Plantilla Usuario'!$B$10:$I$54,$B41)/VLOOKUP($H$2,Tablas!$B$52:$C$59,2)) -> -49856 | G40: =IF('EE.FF Económicos'!$D$54="Soles",HLOOKUP(G$2,'Plantilla Usuario'!$B$10:$I$54,$B41),HLOOKUP(G$2,'Plantilla Usuario'!$B$10:$I$54,$B41)/VLOOKUP($H$2,Tablas!$B$52:$C$59,2)) -> -75085 | H40: =IF('EE.FF Económicos'!$D$54="Soles",HLOOKUP(H$2,'Plantilla Usuario'!$B$10:$I$54,$B41),HLOOKUP(H$2,'Plantilla Usuario'!$B$10:$I$54,$B41)/VLOOKUP($H$2,Tablas!$B$52:$C$59,2)) -> 39531
B41: 39 | C41: Utilidad Operativa | D41: =SUM(D37:D40) -> 743072 | E41: =SUM(E37:E40) -> 786274 | F41: =SUM(F37:F40) -> 948575 | G41: =SUM(G37:G40) -> 793843 | H41: =SUM(H37:H40) -> 916566
B42: 41 | C42: Impuesto | D42: =-29.5%*D41 -> -219206.24 | E42: =-29.5%*E41 -> -231950.83 | F42: =-29.5%*F41 -> -279829.62 | G42: =-29.5%*G41 -> -234183.68 | H42: =-29.5%*H41 -> -270386.97
B43: 42 | C43: Depreciación | D43: =IF('EE.FF Económicos'!$D$54="Soles",HLOOKUP(D$2,'Plantilla Usuario'!$B$10:$I$54,$B39),HLOOKUP(D$2,'Plantilla Usuario'!$B$10:$I$54,$B39)/VLOOKUP($H$2,Tablas!$B$52:$C$59,2)) -> 164314 | E43: =IF('EE.FF Económicos'!$D$54="Soles",HLOOKUP(E$2,'Plantilla Usuario'!$B$10:$I$54,$B39),HLOOKUP(E$2,'Plantilla Usuario'!$B$10:$I$54,$B39)/VLOOKUP($H$2,Tablas!$B$52:$C$59,2)) -> 202775 | F43: =IF('EE.FF Económicos'!$D$54="Soles",HLOOKUP(F$2,'Plantilla Usuario'!$B$10:$I$54,$B39),HLOOKUP(F$2,'Plantilla Usuario'!$B$10:$I$54,$B39)/VLOOKUP($H$2,Tablas!$B$52:$C$59,2)) -> 298028 | G43: =IF('EE.FF Económicos'!$D$54="Soles",HLOOKUP(G$2,'Plantilla Usuario'!$B$10:$I$54,$B39),HLOOKUP(G$2,'Plantilla Usuario'!$B$10:$I$54,$B39)/VLOOKUP($H$2,Tablas!$B$52:$C$59,2)) -> 286071 | H43: =IF('EE.FF Económicos'!$D$54="Soles",HLOOKUP(H$2,'Plantilla Usuario'!$B$10:$I$54,$B39),HLOOKUP(H$2,'Plantilla Usuario'!$B$10:$I$54,$B39)/VLOOKUP($H$2,Tablas!$B$52:$C$59,2)) -> 232476
B44: 43 | C44: Flujo de caja Operativo | D44: =D41+D42+D43 -> 688179.76 | E44: =E41+E42+E43 -> 757098.17 | F44: =F41+F42+F43 -> 966773.38 | G44: =G41+G42+G43 -> 845730.31 | H44: =H41+H42+H43 -> 878655.03
B45: 44
B46: 45
B47: 46 | C47: Cálculo del CAPEX | D47: =D34 -> 2017 | E47: =E34 -> 2018 | F47: =F34 -> 2019 | G47: =G34 -> 2020 | H47: =H34 -> 2021
B48: 47 | C48: Propiedad Planta y Equipo | D48: =IF('EE.FF Económicos'!$D$54="Soles",HLOOKUP(D$2,'Plantilla Usuario'!$B$10:$I$54,$B11),HLOOKUP(D$2,'Plantilla Usuario'!$B$10:$I$54,$B11)/VLOOKUP($H$2,Tablas!$B$52:$C$59,2)) -> 1865624 | E48: =IF('EE.FF Económicos'!$D$54="Soles",HLOOKUP(E$2,'Plantilla Usuario'!$B$10:$I$54,$B11),HLOOKUP(E$2,'Plantilla Usuario'!$B$10:$I$54,$B11)/VLOOKUP($H$2,Tablas!$B$52:$C$59,2)) -> 2537852 | F48: =IF('EE.FF Económicos'!$D$54="Soles",HLOOKUP(F$2,'Plantilla Usuario'!$B$10:$I$54,$B11),HLOOKUP(F$2,'Plantilla Usuario'!$B$10:$I$54,$B11)/VLOOKUP($H$2,Tablas!$B$52:$C$59,2)) -> 3323015 | G48: =IF('EE.FF Económicos'!$D$54="Soles",HLOOKUP(G$2,'Plantilla Usuario'!$B$10:$I$54,$B11),HLOOKUP(G$2,'Plantilla Usuario'!$B$10:$I$54,$B11)/VLOOKUP($H$2,Tablas!$B$52:$C$59,2)) -> 3410774 | H48: =IF('EE.FF Económicos'!$D$54="Soles",HLOOKUP(H$2,'Plantilla Usuario'!$B$10:$I$54,$B11),HLOOKUP(H$2,'Plantilla Usuario'!$B$10:$I$54,$B11)/VLOOKUP($H$2,Tablas!$B$52:$C$59,2)) -> 3343589
B49: 48 | C49: Depreciación acumulada | D49: =IF('EE.FF Económicos'!$D$54="Soles",HLOOKUP(D$2,'Plantilla Usuario'!$B$10:$I$54,$B12),HLOOKUP(D$2,'Plantilla Usuario'!$B$10:$I$54,$B12)/VLOOKUP($H$2,Tablas!$B$52:$C$59,2)) -> 1198090 | E49: =IF('EE.FF Económicos'!$D$54="Soles",HLOOKUP(E$2,'Plantilla Usuario'!$B$10:$I$54,$B12),HLOOKUP(E$2,'Plantilla Usuario'!$B$10:$I$54,$B12)/VLOOKUP($H$2,Tablas!$B$52:$C$59,2)) -> 1361126 | F49: =IF('EE.FF Económicos'!$D$54="Soles",HLOOKUP(F$2,'Plantilla Usuario'!$B$10:$I$54,$B12),HLOOKUP(F$2,'Plantilla Usuario'!$B$10:$I$54,$B12)/VLOOKUP($H$2,Tablas!$B$52:$C$59,2)) -> 1540298 | G49: =IF('EE.FF Económicos'!$D$54="Soles",HLOOKUP(G$2,'Plantilla Usuario'!$B$10:$I$54,$B12),HLOOKUP(G$2,'Plantilla Usuario'!$B$10:$I$54,$B12)/VLOOKUP($H$2,Tablas!$B$52:$C$59,2)) -> 1801309 | H49: =IF('EE.FF Económicos'!$D$54="Soles",HLOOKUP(H$2,'Plantilla Usuario'!$B$10:$I$54,$B12),HLOOKUP(H$2,'Plantilla Usuario'!$B$10:$I$54,$B12)/VLOOKUP($H$2,Tablas!$B$52:$C$59,2)) -> 1973854
B50: 49 | C50: Total Costo de Activos de Adquisición | D50: =D48+D49 -> 3063714 | E50: =E48+E49 -> 3898978 | F50: =F48+F49 -> 4863313 | G50: =G48+G49 -> 5212083 | H50: =H48+H49 -> 5317443
C53: Gradiente | D53: 0.015
C54: Moneda (Estados Financieros) | D54: Soles

Sheet Devaluación
A1: 2021 | N1: 2022 | AA1: 2023 | AN1: 2024 | BA1: 2025
A2: Periodo (años) | B2: Argentina | C2: Brazil | D2: Chile | E2: Colombia | F2: Ecuador | G2: Mexico | H2: Peru | I2: United States | K2: Horizonte del proyecto (en años) | L2: =WACC!$C$6 -> 1 | N2: Periodo (años) | O2: Argentina | P2: Brazil | Q2: Chile | R2: Colombia | S2: Ecuador | T2: Mexico | U2: Peru | V2: United States | X2: Horizonte del proyecto (en años) | Y2: =WACC!$C$6 -> 1 | AA2: Periodo (años) | AB2: Argentina | AC2: Brazil | AD2: Chile | AE2: Colombia | AF2: Ecuador | AG2: Mexico | AH2: Peru | AI2: United States | AK2: Horizonte del proyecto (en años) | AL2: =WACC!$C$6 -> 1 | AN2: Periodo (años) | AO2: Argentina | AP2: Brazil | AQ2: Chile | AR2: Colombia | AS2: Ecuador | AT2: Mexico | AU2: Peru | AV2: United States | AX2: Horizonte del proyecto (en años) | AY2: =WACC!$C$6 -> 1 | BA2: Periodo (años) | BB2: Argentina | BC2: Brazil | BD2: Chile | BE2: Colombia | BF2: Ecuador | BG2: Mexico | BH2: Peru | BI2: United States | BK2: Horizonte del proyecto (en años) | BL2: =WACC!$C$6 -> 1
